<?xml version="1.0"?>
<sdf version="1.9">
  <world name="nav_smoke">
    <physics name="1ms" type="ode">
      <max_step_size>0.001</max_step_size>
      <real_time_factor>1.0</real_time_factor>
      <real_time_update_rate>4000.0</real_time_update_rate>
    </physics>

    <plugin
      filename="gz-sim-physics-system"
      name="gz::sim::systems::Physics">
    </plugin>
    <plugin
      filename="gz-sim-user-commands-system"
      name="gz::sim::systems::UserCommands">
    </plugin>
    <plugin
      filename="gz-sim-scene-broadcaster-system"
      name="gz::sim::systems::SceneBroadcaster">
    </plugin>
    <plugin
      filename="gz-sim-sensors-system"
      name="gz::sim::systems::Sensors">
      <render_engine>ogre2</render_engine>
    </plugin>

    <scene>
      <ambient>0.45 0.45 0.45 1</ambient>
      <background>0.78 0.82 0.86 1</background>
      <shadows>false</shadows>
    </scene>

    <light name="sun" type="directional">
      <pose>0 0 10 0 0 0</pose>
      <diffuse>0.8 0.8 0.8 1</diffuse>
      <specular>0.2 0.2 0.2 1</specular>
      <direction>-0.5 0.2 -0.9</direction>
    </light>

    <model name="ground_plane">
      <static>true</static>
      <link name="link">
        <collision name="collision">
          <geometry>
            <plane>
              <normal>0 0 1</normal>
              <size>12 9</size>
            </plane>
          </geometry>
        </collision>
        <visual name="visual">
          <geometry>
            <plane>
              <normal>0 0 1</normal>
              <size>12 9</size>
            </plane>
          </geometry>
          <material>
            <ambient>0.82 0.82 0.78 1</ambient>
            <diffuse>0.82 0.82 0.78 1</diffuse>
          </material>
        </visual>
      </link>
    </model>

    <model name="test_room">
      <static>true</static>
      <link name="north_wall">
        <pose>0.0 3.3 0.5 0 0 0</pose>
        <collision name="collision">
          <geometry>
            <box>
              <size>10.14 0.14 1.0</size>
            </box>
          </geometry>
        </collision>
        <visual name="visual">
          <geometry>
            <box>
              <size>10.14 0.14 1.0</size>
            </box>
          </geometry>
          <material>
            <ambient>0.55 0.58 0.60 1</ambient>
            <diffuse>0.55 0.58 0.60 1</diffuse>
          </material>
        </visual>
      </link>

      <link name="south_wall">
        <pose>0.0 -3.3 0.5 0 0 0</pose>
        <collision name="collision">
          <geometry>
            <box>
              <size>10.14 0.14 1.0</size>
            </box>
          </geometry>
        </collision>
        <visual name="visual">
          <geometry>
            <box>
              <size>10.14 0.14 1.0</size>
            </box>
          </geometry>
          <material>
            <ambient>0.55 0.58 0.60 1</ambient>
            <diffuse>0.55 0.58 0.60 1</diffuse>
          </material>
        </visual>
      </link>

      <link name="west_wall">
        <pose>-5.0 0.0 0.5 0 0 0</pose>
        <collision name="collision">
          <geometry>
            <box>
              <size>0.14 6.6 1.0</size>
            </box>
          </geometry>
        </collision>
        <visual name="visual">
          <geometry>
            <box>
              <size>0.14 6.6 1.0</size>
            </box>
          </geometry>
          <material>
            <ambient>0.55 0.58 0.60 1</ambient>
            <diffuse>0.55 0.58 0.60 1</diffuse>
          </material>
        </visual>
      </link>

      <link name="east_wall">
        <pose>5.0 0.0 0.5 0 0 0</pose>
        <collision name="collision">
          <geometry>
            <box>
              <size>0.14 6.6 1.0</size>
            </box>
          </geometry>
        </collision>
        <visual name="visual">
          <geometry>
            <box>
              <size>0.14 6.6 1.0</size>
            </box>
          </geometry>
          <material>
            <ambient>0.55 0.58 0.60 1</ambient>
            <diffuse>0.55 0.58 0.60 1</diffuse>
          </material>
        </visual>
      </link>

      <link name="west_partition_south">
        <pose>-1.8 -2.25 0.5 0 0 0</pose>
        <collision name="collision">
          <geometry>
            <box>
              <size>0.14 2.1 1.0</size>
            </box>
          </geometry>
        </collision>
        <visual name="visual">
          <geometry>
            <box>
              <size>0.14 2.1 1.0</size>
            </box>
          </geometry>
          <material>
            <ambient>0.55 0.58 0.60 1</ambient>
            <diffuse>0.55 0.58 0.60 1</diffuse>
          </material>
        </visual>
      </link>

      <link name="west_partition_north">
        <pose>-1.8 1.75 0.5 0 0 0</pose>
        <collision name="collision">
          <geometry>
            <box>
              <size>0.14 3.1 1.0</size>
            </box>
          </geometry>
        </collision>
        <visual name="visual">
          <geometry>
            <box>
              <size>0.14 3.1 1.0</size>
            </box>
          </geometry>
          <material>
            <ambient>0.55 0.58 0.60 1</ambient>
            <diffuse>0.55 0.58 0.60 1</diffuse>
          </material>
        </visual>
      </link>

      <link name="east_partition_south">
        <pose>1.7 -2.05 0.5 0 0 0</pose>
        <collision name="collision">
          <geometry>
            <box>
              <size>0.14 2.5 1.0</size>
            </box>
          </geometry>
        </collision>
        <visual name="visual">
          <geometry>
            <box>
              <size>0.14 2.5 1.0</size>
            </box>
          </geometry>
          <material>
            <ambient>0.55 0.58 0.60 1</ambient>
            <diffuse>0.55 0.58 0.60 1</diffuse>
          </material>
        </visual>
      </link>

      <link name="east_partition_north">
        <pose>1.7 2.45 0.5 0 0 0</pose>
        <collision name="collision">
          <geometry>
            <box>
              <size>0.14 1.7 1.0</size>
            </box>
          </geometry>
        </collision>
        <visual name="visual">
          <geometry>
            <box>
              <size>0.14 1.7 1.0</size>
            </box>
          </geometry>
          <material>
            <ambient>0.55 0.58 0.60 1</ambient>
            <diffuse>0.55 0.58 0.60 1</diffuse>
          </material>
        </visual>
      </link>

      <link name="west_short_wall">
        <pose>-3.2 0.8 0.5 0 0 0</pose>
        <collision name="collision">
          <geometry>
            <box>
              <size>1.8 0.14 1.0</size>
            </box>
          </geometry>
        </collision>
        <visual name="visual">
          <geometry>
            <box>
              <size>1.8 0.14 1.0</size>
            </box>
          </geometry>
          <material>
            <ambient>0.55 0.58 0.60 1</ambient>
            <diffuse>0.55 0.58 0.60 1</diffuse>
          </material>
        </visual>
      </link>

      <link name="middle_short_wall">
        <pose>-0.2 -1.7 0.5 0 0 0</pose>
        <collision name="collision">
          <geometry>
            <box>
              <size>2.0 0.14 1.0</size>
            </box>
          </geometry>
        </collision>
        <visual name="visual">
          <geometry>
            <box>
              <size>2.0 0.14 1.0</size>
            </box>
          </geometry>
          <material>
            <ambient>0.55 0.58 0.60 1</ambient>
            <diffuse>0.55 0.58 0.60 1</diffuse>
          </material>
        </visual>
      </link>

      <link name="east_short_wall">
        <pose>3.45 -1.45 0.5 0 0 0</pose>
        <collision name="collision">
          <geometry>
            <box>
              <size>1.1 0.14 1.0</size>
            </box>
          </geometry>
        </collision>
        <visual name="visual">
          <geometry>
            <box>
              <size>1.1 0.14 1.0</size>
            </box>
          </geometry>
          <material>
            <ambient>0.55 0.58 0.60 1</ambient>
            <diffuse>0.55 0.58 0.60 1</diffuse>
          </material>
        </visual>
      </link>

      <link name="east_divider">
        <pose>3.1 -1.15 0.5 0 0 0</pose>
        <collision name="collision">
          <geometry>
            <box>
              <size>0.14 1.3 1.0</size>
            </box>
          </geometry>
        </collision>
        <visual name="visual">
          <geometry>
            <box>
              <size>0.14 1.3 1.0</size>
            </box>
          </geometry>
          <material>
            <ambient>0.55 0.58 0.60 1</ambient>
            <diffuse>0.55 0.58 0.60 1</diffuse>
          </material>
        </visual>
      </link>

      <link name="west_crate_a">
        <pose>-4.0 -2.25 0.3 0 0 0</pose>
        <collision name="collision">
          <geometry>
            <box>
              <size>0.6 0.6 0.6</size>
            </box>
          </geometry>
        </collision>
        <visual name="visual">
          <geometry>
            <box>
              <size>0.6 0.6 0.6</size>
            </box>
          </geometry>
          <material>
            <ambient>0.78 0.32 0.24 1</ambient>
            <diffuse>0.78 0.32 0.24 1</diffuse>
          </material>
        </visual>
      </link>

      <link name="west_crate_b">
        <pose>-3.55 1.9 0.3 0 0 0</pose>
        <collision name="collision">
          <geometry>
            <box>
              <size>0.5 0.5 0.6</size>
            </box>
          </geometry>
        </collision>
        <visual name="visual">
          <geometry>
            <box>
              <size>0.5 0.5 0.6</size>
            </box>
          </geometry>
          <material>
            <ambient>0.78 0.32 0.24 1</ambient>
            <diffuse>0.78 0.32 0.24 1</diffuse>
          </material>
        </visual>
      </link>

      <link name="middle_column_a">
        <pose>-0.85 1.75 0.3 0 0 0</pose>
        <collision name="collision">
          <geometry>
            <box>
              <size>0.55 0.55 0.6</size>
            </box>
          </geometry>
        </collision>
        <visual name="visual">
          <geometry>
            <box>
              <size>0.55 0.55 0.6</size>
            </box>
          </geometry>
          <material>
            <ambient>0.78 0.32 0.24 1</ambient>
            <diffuse>0.78 0.32 0.24 1</diffuse>
          </material>
        </visual>
      </link>

      <link name="middle_column_b">
        <pose>0.65 -2.35 0.3 0 0 0</pose>
        <collision name="collision">
          <geometry>
            <box>
              <size>0.6 0.6 0.6</size>
            </box>
          </geometry>
        </collision>
        <visual name="visual">
          <geometry>
            <box>
              <size>0.6 0.6 0.6</size>
            </box>
          </geometry>
          <material>
            <ambient>0.78 0.32 0.24 1</ambient>
            <diffuse>0.78 0.32 0.24 1</diffuse>
          </material>
        </visual>
      </link>

      <link name="east_crate_a">
        <pose>2.55 -2.35 0.3 0 0 0</pose>
        <collision name="collision">
          <geometry>
            <box>
              <size>0.65 0.65 0.6</size>
            </box>
          </geometry>
        </collision>
        <visual name="visual">
          <geometry>
            <box>
              <size>0.65 0.65 0.6</size>
            </box>
          </geometry>
          <material>
            <ambient>0.78 0.32 0.24 1</ambient>
            <diffuse>0.78 0.32 0.24 1</diffuse>
          </material>
        </visual>
      </link>

      <link name="east_crate_b">
        <pose>3.85 -0.35 0.3 0 0 0</pose>
        <collision name="collision">
          <geometry>
            <box>
              <size>0.55 0.55 0.6</size>
            </box>
          </geometry>
        </collision>
        <visual name="visual">
          <geometry>
            <box>
              <size>0.55 0.55 0.6</size>
            </box>
          </geometry>
          <material>
            <ambient>0.78 0.32 0.24 1</ambient>
            <diffuse>0.78 0.32 0.24 1</diffuse>
          </material>
        </visual>
      </link>

      <link name="east_crate_c">
        <pose>2.35 2.55 0.3 0 0 0</pose>
        <collision name="collision">
          <geometry>
            <box>
              <size>0.55 0.55 0.6</size>
            </box>
          </geometry>
        </collision>
        <visual name="visual">
          <geometry>
            <box>
              <size>0.55 0.55 0.6</size>
            </box>
          </geometry>
          <material>
            <ambient>0.78 0.32 0.24 1</ambient>
            <diffuse>0.78 0.32 0.24 1</diffuse>
          </material>
        </visual>
      </link>

      <link name="east_shelf">
        <pose>4.35 0.75 0.3 0 0 0</pose>
        <collision name="collision">
          <geometry>
            <box>
              <size>0.5 0.8 0.6</size>
            </box>
          </geometry>
        </collision>
        <visual name="visual">
          <geometry>
            <box>
              <size>0.5 0.8 0.6</size>
            </box>
          </geometry>
          <material>
            <ambient>0.78 0.32 0.24 1</ambient>
            <diffuse>0.78 0.32 0.24 1</diffuse>
          </material>
        </visual>
      </link>

      <link name="east_low_box">
        <pose>4.25 -2.25 0.3 0 0 0</pose>
        <collision name="collision">
          <geometry>
            <box>
              <size>0.5 0.5 0.6</size>
            </box>
          </geometry>
        </collision>
        <visual name="visual">
          <geometry>
            <box>
              <size>0.5 0.5 0.6</size>
            </box>
          </geometry>
          <material>
            <ambient>0.78 0.32 0.24 1</ambient>
            <diffuse>0.78 0.32 0.24 1</diffuse>
          </material>
        </visual>
      </link>
    </model>

    <model name="nav_bot">
      <pose>0 0 0 0 0 0</pose>

      <link name="base_link">
        <inertial>
          <pose>0 0 0.12 0 0 0</pose>
          <mass>2.0</mass>
          <inertia>
            <ixx>0.02</ixx>
            <ixy>0.0</ixy>
            <ixz>0.0</ixz>
            <iyy>0.02</iyy>
            <iyz>0.0</iyz>
            <izz>0.02</izz>
          </inertia>
        </inertial>
        <collision name="collision">
          <pose>0 0 0.12 0 0 0</pose>
          <geometry>
            <cylinder>
              <radius>0.33</radius>
              <length>0.12</length>
            </cylinder>
          </geometry>
        </collision>
        <visual name="visual">
          <pose>0 0 0.12 0 0 0</pose>
          <geometry>
            <cylinder>
              <radius>0.33</radius>
              <length>0.12</length>
            </cylinder>
          </geometry>
          <material>
            <ambient>0.10 0.34 0.72 1</ambient>
            <diffuse>0.10 0.34 0.72 1</diffuse>
          </material>
        </visual>
      </link>

      <link name="left_wheel_link">
        <inertial>
          <pose>0 0.18 0.06 -1.5708 0 0</pose>
          <mass>0.2</mass>
          <inertia>
            <ixx>0.001</ixx>
            <ixy>0.0</ixy>
            <ixz>0.0</ixz>
            <iyy>0.001</iyy>
            <iyz>0.0</iyz>
            <izz>0.001</izz>
          </inertia>
        </inertial>
        <collision name="collision">
          <pose>0 0.18 0.06 -1.5708 0 0</pose>
          <geometry>
            <cylinder>
              <radius>0.06</radius>
              <length>0.04</length>
            </cylinder>
          </geometry>
          <surface>
            <friction>
              <ode>
                <mu>1.0</mu>
                <mu2>1.0</mu2>
              </ode>
            </friction>
          </surface>
        </collision>
        <visual name="visual">
          <pose>0 0.18 0.06 -1.5708 0 0</pose>
          <geometry>
            <cylinder>
              <radius>0.06</radius>
              <length>0.04</length>
            </cylinder>
          </geometry>
          <material>
            <ambient>0.04 0.04 0.04 1</ambient>
            <diffuse>0.04 0.04 0.04 1</diffuse>
          </material>
        </visual>
      </link>

      <link name="right_wheel_link">
        <inertial>
          <pose>0 -0.18 0.06 -1.5708 0 0</pose>
          <mass>0.2</mass>
          <inertia>
            <ixx>0.001</ixx>
            <ixy>0.0</ixy>
            <ixz>0.0</ixz>
            <iyy>0.001</iyy>
            <iyz>0.0</iyz>
            <izz>0.001</izz>
          </inertia>
        </inertial>
        <collision name="collision">
          <pose>0 -0.18 0.06 -1.5708 0 0</pose>
          <geometry>
            <cylinder>
              <radius>0.06</radius>
              <length>0.04</length>
            </cylinder>
          </geometry>
          <surface>
            <friction>
              <ode>
                <mu>1.0</mu>
                <mu2>1.0</mu2>
              </ode>
            </friction>
          </surface>
        </collision>
        <visual name="visual">
          <pose>0 -0.18 0.06 -1.5708 0 0</pose>
          <geometry>
            <cylinder>
              <radius>0.06</radius>
              <length>0.04</length>
            </cylinder>
          </geometry>
          <material>
            <ambient>0.04 0.04 0.04 1</ambient>
            <diffuse>0.04 0.04 0.04 1</diffuse>
          </material>
        </visual>
      </link>

      <link name="caster_link">
        <pose>-0.15 0 0.035 0 0 0</pose>
        <inertial>
          <mass>0.05</mass>
          <inertia>
            <ixx>0.0001</ixx>
            <ixy>0.0</ixy>
            <ixz>0.0</ixz>
            <iyy>0.0001</iyy>
            <iyz>0.0</iyz>
            <izz>0.0001</izz>
          </inertia>
        </inertial>
        <collision name="collision">
          <geometry>
            <sphere>
              <radius>0.035</radius>
            </sphere>
          </geometry>
        </collision>
        <visual name="visual">
          <geometry>
            <sphere>
              <radius>0.035</radius>
            </sphere>
          </geometry>
          <material>
            <ambient>0.04 0.04 0.04 1</ambient>
            <diffuse>0.04 0.04 0.04 1</diffuse>
          </material>
        </visual>
      </link>

      <link name="base_scan">
        <pose>0 0 0.23 0 0 0</pose>
        <inertial>
          <mass>0.05</mass>
          <inertia>
            <ixx>0.0001</ixx>
            <ixy>0.0</ixy>
            <ixz>0.0</ixz>
            <iyy>0.0001</iyy>
            <iyz>0.0</iyz>
            <izz>0.0001</izz>
          </inertia>
        </inertial>
        <collision name="collision">
          <geometry>
            <cylinder>
              <radius>0.055</radius>
              <length>0.05</length>
            </cylinder>
          </geometry>
        </collision>
        <visual name="visual">
          <geometry>
            <cylinder>
              <radius>0.055</radius>
              <length>0.05</length>
            </cylinder>
          </geometry>
          <material>
            <ambient>0.05 0.05 0.05 1</ambient>
            <diffuse>0.05 0.05 0.05 1</diffuse>
          </material>
        </visual>
        <sensor name="lidar" type="gpu_lidar">
          <always_on>true</always_on>
          <visualize>true</visualize>
          <update_rate>10</update_rate>
          <topic>/scan</topic>
          <gz_frame_id>base_scan</gz_frame_id>
          <ray>
            <scan>
              <horizontal>
                <samples>360</samples>
                <resolution>1</resolution>
                <min_angle>-3.14159</min_angle>
                <max_angle>3.14159</max_angle>
              </horizontal>
            </scan>
            <range>
              <min>0.05</min>
              <max>8.0</max>
              <resolution>0.01</resolution>
            </range>
          </ray>
        </sensor>
      </link>

      <joint name="left_wheel_joint" type="revolute">
        <parent>base_link</parent>
        <child>left_wheel_link</child>
        <pose>0 0.18 0.06 -1.5708 0 0</pose>
        <axis>
          <xyz>0 0 1</xyz>
        </axis>
      </joint>

      <joint name="right_wheel_joint" type="revolute">
        <parent>base_link</parent>
        <child>right_wheel_link</child>
        <pose>0 -0.18 0.06 -1.5708 0 0</pose>
        <axis>
          <xyz>0 0 1</xyz>
        </axis>
      </joint>

      <joint name="caster_joint" type="ball">
        <parent>base_link</parent>
        <child>caster_link</child>
      </joint>

      <joint name="lidar_joint" type="fixed">
        <parent>base_link</parent>
        <child>base_scan</child>
        <pose>0 0 0.23 0 0 0</pose>
      </joint>

      <plugin
        filename="gz-sim-diff-drive-system"
        name="gz::sim::systems::DiffDrive">
        <left_joint>left_wheel_joint</left_joint>
        <right_joint>right_wheel_joint</right_joint>
        <wheel_separation>0.36</wheel_separation>
        <wheel_radius>0.06</wheel_radius>
        <odom_publish_frequency>30</odom_publish_frequency>
        <topic>/cmd_vel</topic>
        <odom_topic>/odom</odom_topic>
        <tf_topic>/tf</tf_topic>
        <frame_id>odom</frame_id>
        <child_frame_id>base_link</child_frame_id>
        <min_linear_velocity>-0.25</min_linear_velocity>
        <max_linear_velocity>0.25</max_linear_velocity>
        <min_angular_velocity>-1.2</min_angular_velocity>
        <max_angular_velocity>1.2</max_angular_velocity>
        <min_linear_acceleration>-0.5</min_linear_acceleration>
        <max_linear_acceleration>0.5</max_linear_acceleration>
        <min_angular_acceleration>-1.5</min_angular_acceleration>
        <max_angular_acceleration>1.5</max_angular_acceleration>
      </plugin>
    </model>
  </world>
</sdf>
